[2023-08-06T22:02:35.428+0000] {taskinstance.py:1103} INFO - Dependencies all met for dep_context=non-requeueable deps ti=<TaskInstance: 7_da_temps.hit_api manual__2023-08-06T22:02:34.670121+00:00 [queued]>
[2023-08-06T22:02:35.433+0000] {taskinstance.py:1103} INFO - Dependencies all met for dep_context=requeueable deps ti=<TaskInstance: 7_da_temps.hit_api manual__2023-08-06T22:02:34.670121+00:00 [queued]>
[2023-08-06T22:02:35.433+0000] {taskinstance.py:1308} INFO - Starting attempt 1 of 1
[2023-08-06T22:02:35.439+0000] {taskinstance.py:1327} INFO - Executing <Task(PythonOperator): hit_api> on 2023-08-06 22:02:34.670121+00:00
[2023-08-06T22:02:35.444+0000] {standard_task_runner.py:57} INFO - Started process 4758 to run task
[2023-08-06T22:02:35.447+0000] {standard_task_runner.py:84} INFO - Running: ['***', 'tasks', 'run', '7_da_temps', 'hit_api', 'manual__2023-08-06T22:02:34.670121+00:00', '--job-id', '42', '--raw', '--subdir', 'DAGS_FOLDER/7_da_weather/7_da_temps.py', '--cfg-path', '/tmp/tmpzgawze79']
[2023-08-06T22:02:35.450+0000] {standard_task_runner.py:85} INFO - Job 42: Subtask hit_api
[2023-08-06T22:02:35.480+0000] {task_command.py:410} INFO - Running <TaskInstance: 7_da_temps.hit_api manual__2023-08-06T22:02:34.670121+00:00 [running]> on host ed9f4b70d884
[2023-08-06T22:02:35.521+0000] {taskinstance.py:1545} INFO - Exporting env vars: AIRFLOW_CTX_DAG_OWNER='scott' AIRFLOW_CTX_DAG_ID='7_da_temps' AIRFLOW_CTX_TASK_ID='hit_api' AIRFLOW_CTX_EXECUTION_DATE='2023-08-06T22:02:34.670121+00:00' AIRFLOW_CTX_TRY_NUMBER='1' AIRFLOW_CTX_DAG_RUN_ID='manual__2023-08-06T22:02:34.670121+00:00'
[2023-08-06T22:02:36.996+0000] {logging_mixin.py:150} INFO - <pyowm.weatherapi25.one_call.OneCall - lat=34.0978, lon=-117.886, retrieval_time=1691359356>
[2023-08-06T22:02:36.998+0000] {taskinstance.py:1824} ERROR - Task failed with exception
Traceback (most recent call last):
  File "/home/airflow/.local/lib/python3.11/site-packages/airflow/operators/python.py", line 181, in execute
    return_value = self.execute_callable()
                   ^^^^^^^^^^^^^^^^^^^^^^^
  File "/home/airflow/.local/lib/python3.11/site-packages/airflow/operators/python.py", line 198, in execute_callable
    return self.python_callable(*self.op_args, **self.op_kwargs)
           ^^^^^^^^^^^^^^^^^^^^^^^^^^^^^^^^^^^^^^^^^^^^^^^^^^^^^
  File "/opt/airflow/dags/7_da_weather/7_da_temps.py", line 30, in hit_open_weather
    for i in back_call:
TypeError: 'OneCall' object is not iterable
[2023-08-06T22:02:37.007+0000] {taskinstance.py:1345} INFO - Marking task as FAILED. dag_id=7_da_temps, task_id=hit_api, execution_date=20230806T220234, start_date=20230806T220235, end_date=20230806T220237
[2023-08-06T22:02:37.014+0000] {standard_task_runner.py:104} ERROR - Failed to execute job 42 for task hit_api ('OneCall' object is not iterable; 4758)
[2023-08-06T22:02:37.062+0000] {local_task_job_runner.py:225} INFO - Task exited with return code 1
[2023-08-06T22:02:37.075+0000] {taskinstance.py:2653} INFO - 0 downstream tasks scheduled from follow-on schedule check
