[2023-08-05T05:48:13.383+0000] {taskinstance.py:1103} INFO - Dependencies all met for dep_context=non-requeueable deps ti=<TaskInstance: 7_da_temps.hit_api manual__2023-08-05T05:48:12.459765+00:00 [queued]>
[2023-08-05T05:48:13.387+0000] {taskinstance.py:1103} INFO - Dependencies all met for dep_context=requeueable deps ti=<TaskInstance: 7_da_temps.hit_api manual__2023-08-05T05:48:12.459765+00:00 [queued]>
[2023-08-05T05:48:13.387+0000] {taskinstance.py:1308} INFO - Starting attempt 1 of 1
[2023-08-05T05:48:13.393+0000] {taskinstance.py:1327} INFO - Executing <Task(PythonOperator): hit_api> on 2023-08-05 05:48:12.459765+00:00
[2023-08-05T05:48:13.398+0000] {standard_task_runner.py:57} INFO - Started process 415 to run task
[2023-08-05T05:48:13.401+0000] {standard_task_runner.py:84} INFO - Running: ['***', 'tasks', 'run', '7_da_temps', 'hit_api', 'manual__2023-08-05T05:48:12.459765+00:00', '--job-id', '29', '--raw', '--subdir', 'DAGS_FOLDER/7_da_weather/7_da_temps.py', '--cfg-path', '/tmp/tmptipq966j']
[2023-08-05T05:48:13.404+0000] {standard_task_runner.py:85} INFO - Job 29: Subtask hit_api
[2023-08-05T05:48:13.435+0000] {task_command.py:410} INFO - Running <TaskInstance: 7_da_temps.hit_api manual__2023-08-05T05:48:12.459765+00:00 [running]> on host 87416e0da69d
[2023-08-05T05:48:13.479+0000] {taskinstance.py:1545} INFO - Exporting env vars: AIRFLOW_CTX_DAG_OWNER='scott' AIRFLOW_CTX_DAG_ID='7_da_temps' AIRFLOW_CTX_TASK_ID='hit_api' AIRFLOW_CTX_EXECUTION_DATE='2023-08-05T05:48:12.459765+00:00' AIRFLOW_CTX_TRY_NUMBER='1' AIRFLOW_CTX_DAG_RUN_ID='manual__2023-08-05T05:48:12.459765+00:00'
[2023-08-05T05:48:14.071+0000] {logging_mixin.py:150} INFO - {'temp': 71.1, 'temp_max': 76.48, 'temp_min': 65.08, 'feels_like': 71.06, 'temp_kf': None}
[2023-08-05T05:48:14.074+0000] {taskinstance.py:1824} ERROR - Task failed with exception
Traceback (most recent call last):
  File "/home/airflow/.local/lib/python3.11/site-packages/airflow/operators/python.py", line 181, in execute
    return_value = self.execute_callable()
                   ^^^^^^^^^^^^^^^^^^^^^^^
  File "/home/airflow/.local/lib/python3.11/site-packages/airflow/operators/python.py", line 198, in execute_callable
    return self.python_callable(*self.op_args, **self.op_kwargs)
           ^^^^^^^^^^^^^^^^^^^^^^^^^^^^^^^^^^^^^^^^^^^^^^^^^^^^^
  File "/opt/airflow/dags/7_da_weather/7_da_temps.py", line 24, in hit_open_weather
    one_call = mgr.one_call(location_name)
               ^^^^^^^^^^^^^^^^^^^^^^^^^^^
TypeError: WeatherManager.one_call() missing 1 required positional argument: 'lon'
[2023-08-05T05:48:14.090+0000] {taskinstance.py:1345} INFO - Marking task as FAILED. dag_id=7_da_temps, task_id=hit_api, execution_date=20230805T054812, start_date=20230805T054813, end_date=20230805T054814
[2023-08-05T05:48:14.100+0000] {standard_task_runner.py:104} ERROR - Failed to execute job 29 for task hit_api (WeatherManager.one_call() missing 1 required positional argument: 'lon'; 415)
[2023-08-05T05:48:14.151+0000] {local_task_job_runner.py:225} INFO - Task exited with return code 1
[2023-08-05T05:48:14.162+0000] {taskinstance.py:2653} INFO - 0 downstream tasks scheduled from follow-on schedule check
