[2023-08-05T05:53:40.899+0000] {taskinstance.py:1103} INFO - Dependencies all met for dep_context=non-requeueable deps ti=<TaskInstance: 7_da_temps.hit_api manual__2023-08-05T05:53:39.856881+00:00 [queued]>
[2023-08-05T05:53:40.903+0000] {taskinstance.py:1103} INFO - Dependencies all met for dep_context=requeueable deps ti=<TaskInstance: 7_da_temps.hit_api manual__2023-08-05T05:53:39.856881+00:00 [queued]>
[2023-08-05T05:53:40.904+0000] {taskinstance.py:1308} INFO - Starting attempt 1 of 1
[2023-08-05T05:53:40.909+0000] {taskinstance.py:1327} INFO - Executing <Task(PythonOperator): hit_api> on 2023-08-05 05:53:39.856881+00:00
[2023-08-05T05:53:40.914+0000] {standard_task_runner.py:57} INFO - Started process 1613 to run task
[2023-08-05T05:53:40.917+0000] {standard_task_runner.py:84} INFO - Running: ['***', 'tasks', 'run', '7_da_temps', 'hit_api', 'manual__2023-08-05T05:53:39.856881+00:00', '--job-id', '32', '--raw', '--subdir', 'DAGS_FOLDER/7_da_weather/7_da_temps.py', '--cfg-path', '/tmp/tmpjbuubssi']
[2023-08-05T05:53:40.920+0000] {standard_task_runner.py:85} INFO - Job 32: Subtask hit_api
[2023-08-05T05:53:40.952+0000] {task_command.py:410} INFO - Running <TaskInstance: 7_da_temps.hit_api manual__2023-08-05T05:53:39.856881+00:00 [running]> on host 87416e0da69d
[2023-08-05T05:53:40.992+0000] {taskinstance.py:1545} INFO - Exporting env vars: AIRFLOW_CTX_DAG_OWNER='scott' AIRFLOW_CTX_DAG_ID='7_da_temps' AIRFLOW_CTX_TASK_ID='hit_api' AIRFLOW_CTX_EXECUTION_DATE='2023-08-05T05:53:39.856881+00:00' AIRFLOW_CTX_TRY_NUMBER='1' AIRFLOW_CTX_DAG_RUN_ID='manual__2023-08-05T05:53:39.856881+00:00'
[2023-08-05T05:53:41.555+0000] {logging_mixin.py:150} INFO - {'temp': 71.1, 'temp_max': 76.48, 'temp_min': 65.08, 'feels_like': 71.06, 'temp_kf': None}
[2023-08-05T05:53:41.909+0000] {taskinstance.py:1824} ERROR - Task failed with exception
Traceback (most recent call last):
  File "/home/airflow/.local/lib/python3.11/site-packages/airflow/operators/python.py", line 181, in execute
    return_value = self.execute_callable()
                   ^^^^^^^^^^^^^^^^^^^^^^^
  File "/home/airflow/.local/lib/python3.11/site-packages/airflow/operators/python.py", line 198, in execute_callable
    return self.python_callable(*self.op_args, **self.op_kwargs)
           ^^^^^^^^^^^^^^^^^^^^^^^^^^^^^^^^^^^^^^^^^^^^^^^^^^^^^
  File "/opt/airflow/dags/7_da_weather/7_da_temps.py", line 25, in hit_open_weather
    one_call = mgr.one_call(lat=lat, lon=lon)
               ^^^^^^^^^^^^^^^^^^^^^^^^^^^^^^
  File "/home/airflow/.local/lib/python3.11/site-packages/pyowm/weatherapi25/weather_manager.py", line 531, in one_call
    _, json_data = self.http_client.get_json(ONE_CALL_URI, params=params)
                   ^^^^^^^^^^^^^^^^^^^^^^^^^^^^^^^^^^^^^^^^^^^^^^^^^^^^^^
  File "/home/airflow/.local/lib/python3.11/site-packages/pyowm/commons/http_client.py", line 158, in get_json
    HttpClient.check_status_code(resp.status_code, resp.text)
  File "/home/airflow/.local/lib/python3.11/site-packages/pyowm/commons/http_client.py", line 313, in check_status_code
    raise exceptions.UnauthorizedError('Invalid API Key provided')
pyowm.commons.exceptions.UnauthorizedError: Invalid API Key provided
[2023-08-05T05:53:41.938+0000] {taskinstance.py:1345} INFO - Marking task as FAILED. dag_id=7_da_temps, task_id=hit_api, execution_date=20230805T055339, start_date=20230805T055340, end_date=20230805T055341
[2023-08-05T05:53:41.953+0000] {standard_task_runner.py:104} ERROR - Failed to execute job 32 for task hit_api (Invalid API Key provided; 1613)
[2023-08-05T05:53:42.007+0000] {local_task_job_runner.py:225} INFO - Task exited with return code 1
[2023-08-05T05:53:42.020+0000] {taskinstance.py:2653} INFO - 0 downstream tasks scheduled from follow-on schedule check
