[2023-08-16T18:35:25.195+0000] {taskinstance.py:1103} INFO - Dependencies all met for dep_context=non-requeueable deps ti=<TaskInstance: 7_da_temps.hit_open_meteo scheduled__2023-08-15T18:20:43.635818+00:00 [queued]>
[2023-08-16T18:35:25.201+0000] {taskinstance.py:1103} INFO - Dependencies all met for dep_context=requeueable deps ti=<TaskInstance: 7_da_temps.hit_open_meteo scheduled__2023-08-15T18:20:43.635818+00:00 [queued]>
[2023-08-16T18:35:25.201+0000] {taskinstance.py:1308} INFO - Starting attempt 1 of 1
[2023-08-16T18:35:25.207+0000] {taskinstance.py:1327} INFO - Executing <Task(PythonOperator): hit_open_meteo> on 2023-08-15 18:20:43.635818+00:00
[2023-08-16T18:35:25.212+0000] {standard_task_runner.py:57} INFO - Started process 43160 to run task
[2023-08-16T18:35:25.215+0000] {standard_task_runner.py:84} INFO - Running: ['***', 'tasks', 'run', '7_da_temps', 'hit_open_meteo', 'scheduled__2023-08-15T18:20:43.635818+00:00', '--job-id', '92', '--raw', '--subdir', 'DAGS_FOLDER/7_da_weather/7_da_temps.py', '--cfg-path', '/tmp/tmpb9h50ot4']
[2023-08-16T18:35:25.218+0000] {standard_task_runner.py:85} INFO - Job 92: Subtask hit_open_meteo
[2023-08-16T18:35:25.262+0000] {task_command.py:410} INFO - Running <TaskInstance: 7_da_temps.hit_open_meteo scheduled__2023-08-15T18:20:43.635818+00:00 [running]> on host 199121aa9c86
[2023-08-16T18:35:25.521+0000] {taskinstance.py:1545} INFO - Exporting env vars: AIRFLOW_CTX_DAG_OWNER='scott' AIRFLOW_CTX_DAG_ID='7_da_temps' AIRFLOW_CTX_TASK_ID='hit_open_meteo' AIRFLOW_CTX_EXECUTION_DATE='2023-08-15T18:20:43.635818+00:00' AIRFLOW_CTX_TRY_NUMBER='1' AIRFLOW_CTX_DAG_RUN_ID='scheduled__2023-08-15T18:20:43.635818+00:00'
[2023-08-16T18:35:25.548+0000] {taskinstance.py:1824} ERROR - Task failed with exception
Traceback (most recent call last):
  File "/home/airflow/.local/lib/python3.11/site-packages/urllib3/connection.py", line 203, in _new_conn
    sock = connection.create_connection(
           ^^^^^^^^^^^^^^^^^^^^^^^^^^^^^
  File "/home/airflow/.local/lib/python3.11/site-packages/urllib3/util/connection.py", line 60, in create_connection
    for res in socket.getaddrinfo(host, port, family, socket.SOCK_STREAM):
               ^^^^^^^^^^^^^^^^^^^^^^^^^^^^^^^^^^^^^^^^^^^^^^^^^^^^^^^^^^
  File "/usr/local/lib/python3.11/socket.py", line 962, in getaddrinfo
    for res in _socket.getaddrinfo(host, port, family, type, proto, flags):
               ^^^^^^^^^^^^^^^^^^^^^^^^^^^^^^^^^^^^^^^^^^^^^^^^^^^^^^^^^^^
socket.gaierror: [Errno -2] Name or service not known

The above exception was the direct cause of the following exception:

Traceback (most recent call last):
  File "/home/airflow/.local/lib/python3.11/site-packages/urllib3/connectionpool.py", line 790, in urlopen
    response = self._make_request(
               ^^^^^^^^^^^^^^^^^^^
  File "/home/airflow/.local/lib/python3.11/site-packages/urllib3/connectionpool.py", line 491, in _make_request
    raise new_e
  File "/home/airflow/.local/lib/python3.11/site-packages/urllib3/connectionpool.py", line 467, in _make_request
    self._validate_conn(conn)
  File "/home/airflow/.local/lib/python3.11/site-packages/urllib3/connectionpool.py", line 1092, in _validate_conn
    conn.connect()
  File "/home/airflow/.local/lib/python3.11/site-packages/urllib3/connection.py", line 611, in connect
    self.sock = sock = self._new_conn()
                       ^^^^^^^^^^^^^^^^
  File "/home/airflow/.local/lib/python3.11/site-packages/urllib3/connection.py", line 210, in _new_conn
    raise NameResolutionError(self.host, self, e) from e
urllib3.exceptions.NameResolutionError: <urllib3.connection.HTTPSConnection object at 0xffff7c1dd7d0>: Failed to resolve 'api.open-meteo.com' ([Errno -2] Name or service not known)

The above exception was the direct cause of the following exception:

Traceback (most recent call last):
  File "/home/airflow/.local/lib/python3.11/site-packages/requests/adapters.py", line 486, in send
    resp = conn.urlopen(
           ^^^^^^^^^^^^^
  File "/home/airflow/.local/lib/python3.11/site-packages/urllib3/connectionpool.py", line 844, in urlopen
    retries = retries.increment(
              ^^^^^^^^^^^^^^^^^^
  File "/home/airflow/.local/lib/python3.11/site-packages/urllib3/util/retry.py", line 515, in increment
    raise MaxRetryError(_pool, url, reason) from reason  # type: ignore[arg-type]
    ^^^^^^^^^^^^^^^^^^^^^^^^^^^^^^^^^^^^^^^^^^^^^^^^^^^
urllib3.exceptions.MaxRetryError: HTTPSConnectionPool(host='api.open-meteo.com', port=443): Max retries exceeded with url: /v1/forecast?latitude=34.09&longitude=-117.8903&hourly=temperature_2m%2Capparent_temperature%2Ccloudcover%2Cprecipitation_probability%2Cwindspeed_10m&timezone=America%2FLos_Angeles&temperature_unit=fahrenheit (Caused by NameResolutionError("<urllib3.connection.HTTPSConnection object at 0xffff7c1dd7d0>: Failed to resolve 'api.open-meteo.com' ([Errno -2] Name or service not known)"))

During handling of the above exception, another exception occurred:

Traceback (most recent call last):
  File "/home/airflow/.local/lib/python3.11/site-packages/airflow/operators/python.py", line 181, in execute
    return_value = self.execute_callable()
                   ^^^^^^^^^^^^^^^^^^^^^^^
  File "/home/airflow/.local/lib/python3.11/site-packages/airflow/operators/python.py", line 198, in execute_callable
    return self.python_callable(*self.op_args, **self.op_kwargs)
           ^^^^^^^^^^^^^^^^^^^^^^^^^^^^^^^^^^^^^^^^^^^^^^^^^^^^^
  File "/opt/airflow/dags/7_da_weather/7_da_temps.py", line 28, in hit_open_meteo
    data = temps_forecast_7da()
           ^^^^^^^^^^^^^^^^^^^^
  File "/opt/airflow/utils/meteo_wrapper.py", line 40, in temps_forecast_7da
    r = requests.get(
        ^^^^^^^^^^^^^
  File "/home/airflow/.local/lib/python3.11/site-packages/requests/api.py", line 73, in get
    return request("get", url, params=params, **kwargs)
           ^^^^^^^^^^^^^^^^^^^^^^^^^^^^^^^^^^^^^^^^^^^^
  File "/home/airflow/.local/lib/python3.11/site-packages/requests/api.py", line 59, in request
    return session.request(method=method, url=url, **kwargs)
           ^^^^^^^^^^^^^^^^^^^^^^^^^^^^^^^^^^^^^^^^^^^^^^^^^
  File "/home/airflow/.local/lib/python3.11/site-packages/requests/sessions.py", line 589, in request
    resp = self.send(prep, **send_kwargs)
           ^^^^^^^^^^^^^^^^^^^^^^^^^^^^^^
  File "/home/airflow/.local/lib/python3.11/site-packages/requests/sessions.py", line 703, in send
    r = adapter.send(request, **kwargs)
        ^^^^^^^^^^^^^^^^^^^^^^^^^^^^^^^
  File "/home/airflow/.local/lib/python3.11/site-packages/requests/adapters.py", line 519, in send
    raise ConnectionError(e, request=request)
requests.exceptions.ConnectionError: HTTPSConnectionPool(host='api.open-meteo.com', port=443): Max retries exceeded with url: /v1/forecast?latitude=34.09&longitude=-117.8903&hourly=temperature_2m%2Capparent_temperature%2Ccloudcover%2Cprecipitation_probability%2Cwindspeed_10m&timezone=America%2FLos_Angeles&temperature_unit=fahrenheit (Caused by NameResolutionError("<urllib3.connection.HTTPSConnection object at 0xffff7c1dd7d0>: Failed to resolve 'api.open-meteo.com' ([Errno -2] Name or service not known)"))
[2023-08-16T18:35:25.563+0000] {taskinstance.py:1345} INFO - Marking task as FAILED. dag_id=7_da_temps, task_id=hit_open_meteo, execution_date=20230815T182043, start_date=20230816T183525, end_date=20230816T183525
[2023-08-16T18:35:25.569+0000] {standard_task_runner.py:104} ERROR - Failed to execute job 92 for task hit_open_meteo (HTTPSConnectionPool(host='api.open-meteo.com', port=443): Max retries exceeded with url: /v1/forecast?latitude=34.09&longitude=-117.8903&hourly=temperature_2m%2Capparent_temperature%2Ccloudcover%2Cprecipitation_probability%2Cwindspeed_10m&timezone=America%2FLos_Angeles&temperature_unit=fahrenheit (Caused by NameResolutionError("<urllib3.connection.HTTPSConnection object at 0xffff7c1dd7d0>: Failed to resolve 'api.open-meteo.com' ([Errno -2] Name or service not known)")); 43160)
[2023-08-16T18:35:25.642+0000] {local_task_job_runner.py:225} INFO - Task exited with return code 1
[2023-08-16T18:35:25.657+0000] {taskinstance.py:2653} INFO - 0 downstream tasks scheduled from follow-on schedule check
