[2023-08-05T05:41:06.633+0000] {taskinstance.py:1103} INFO - Dependencies all met for dep_context=non-requeueable deps ti=<TaskInstance: 7_da_temps.hit_api manual__2023-08-05T05:41:05.288162+00:00 [queued]>
[2023-08-05T05:41:06.638+0000] {taskinstance.py:1103} INFO - Dependencies all met for dep_context=requeueable deps ti=<TaskInstance: 7_da_temps.hit_api manual__2023-08-05T05:41:05.288162+00:00 [queued]>
[2023-08-05T05:41:06.639+0000] {taskinstance.py:1308} INFO - Starting attempt 1 of 1
[2023-08-05T05:41:06.645+0000] {taskinstance.py:1327} INFO - Executing <Task(PythonOperator): hit_api> on 2023-08-05 05:41:05.288162+00:00
[2023-08-05T05:41:06.650+0000] {standard_task_runner.py:57} INFO - Started process 305 to run task
[2023-08-05T05:41:06.655+0000] {standard_task_runner.py:84} INFO - Running: ['***', 'tasks', 'run', '7_da_temps', 'hit_api', 'manual__2023-08-05T05:41:05.288162+00:00', '--job-id', '25', '--raw', '--subdir', 'DAGS_FOLDER/7_da_weather/7_da_temps.py', '--cfg-path', '/tmp/tmp2t17rky5']
[2023-08-05T05:41:06.660+0000] {standard_task_runner.py:85} INFO - Job 25: Subtask hit_api
[2023-08-05T05:41:06.723+0000] {task_command.py:410} INFO - Running <TaskInstance: 7_da_temps.hit_api manual__2023-08-05T05:41:05.288162+00:00 [running]> on host 87416e0da69d
[2023-08-05T05:41:06.782+0000] {taskinstance.py:1545} INFO - Exporting env vars: AIRFLOW_CTX_DAG_OWNER='scott' AIRFLOW_CTX_DAG_ID='7_da_temps' AIRFLOW_CTX_TASK_ID='hit_api' AIRFLOW_CTX_EXECUTION_DATE='2023-08-05T05:41:05.288162+00:00' AIRFLOW_CTX_TRY_NUMBER='1' AIRFLOW_CTX_DAG_RUN_ID='manual__2023-08-05T05:41:05.288162+00:00'
[2023-08-05T05:41:07.297+0000] {logging_mixin.py:150} INFO - {'temp': 71.64, 'temp_max': 76.5, 'temp_min': 65.1, 'feels_like': 71.55, 'temp_kf': None}
[2023-08-05T05:41:07.677+0000] {taskinstance.py:1824} ERROR - Task failed with exception
Traceback (most recent call last):
  File "/home/airflow/.local/lib/python3.11/site-packages/airflow/operators/python.py", line 181, in execute
    return_value = self.execute_callable()
                   ^^^^^^^^^^^^^^^^^^^^^^^
  File "/home/airflow/.local/lib/python3.11/site-packages/airflow/operators/python.py", line 198, in execute_callable
    return self.python_callable(*self.op_args, **self.op_kwargs)
           ^^^^^^^^^^^^^^^^^^^^^^^^^^^^^^^^^^^^^^^^^^^^^^^^^^^^^
  File "/opt/airflow/dags/7_da_weather/7_da_temps.py", line 23, in hit_open_weather
    daily_forecaster = mgr.forecast_at_place("Covina, US", "daily")
                       ^^^^^^^^^^^^^^^^^^^^^^^^^^^^^^^^^^^^^^^^^^^^
  File "/home/airflow/.local/lib/python3.11/site-packages/pyowm/weatherapi25/weather_manager.py", line 291, in forecast_at_place
    _, json_data = self.http_client.get_json(uri, params=params)
                   ^^^^^^^^^^^^^^^^^^^^^^^^^^^^^^^^^^^^^^^^^^^^^
  File "/home/airflow/.local/lib/python3.11/site-packages/pyowm/commons/http_client.py", line 158, in get_json
    HttpClient.check_status_code(resp.status_code, resp.text)
  File "/home/airflow/.local/lib/python3.11/site-packages/pyowm/commons/http_client.py", line 313, in check_status_code
    raise exceptions.UnauthorizedError('Invalid API Key provided')
pyowm.commons.exceptions.UnauthorizedError: Invalid API Key provided
[2023-08-05T05:41:07.717+0000] {taskinstance.py:1345} INFO - Marking task as FAILED. dag_id=7_da_temps, task_id=hit_api, execution_date=20230805T054105, start_date=20230805T054106, end_date=20230805T054107
[2023-08-05T05:41:07.732+0000] {standard_task_runner.py:104} ERROR - Failed to execute job 25 for task hit_api (Invalid API Key provided; 305)
[2023-08-05T05:41:07.770+0000] {local_task_job_runner.py:225} INFO - Task exited with return code 1
[2023-08-05T05:41:07.784+0000] {taskinstance.py:2653} INFO - 0 downstream tasks scheduled from follow-on schedule check
