[2023-08-05T05:50:43.554+0000] {taskinstance.py:1103} INFO - Dependencies all met for dep_context=non-requeueable deps ti=<TaskInstance: 7_da_temps.hit_api manual__2023-08-05T05:50:42.800896+00:00 [queued]>
[2023-08-05T05:50:43.559+0000] {taskinstance.py:1103} INFO - Dependencies all met for dep_context=requeueable deps ti=<TaskInstance: 7_da_temps.hit_api manual__2023-08-05T05:50:42.800896+00:00 [queued]>
[2023-08-05T05:50:43.559+0000] {taskinstance.py:1308} INFO - Starting attempt 1 of 1
[2023-08-05T05:50:43.564+0000] {taskinstance.py:1327} INFO - Executing <Task(PythonOperator): hit_api> on 2023-08-05 05:50:42.800896+00:00
[2023-08-05T05:50:43.569+0000] {standard_task_runner.py:57} INFO - Started process 453 to run task
[2023-08-05T05:50:43.573+0000] {standard_task_runner.py:84} INFO - Running: ['***', 'tasks', 'run', '7_da_temps', 'hit_api', 'manual__2023-08-05T05:50:42.800896+00:00', '--job-id', '30', '--raw', '--subdir', 'DAGS_FOLDER/7_da_weather/7_da_temps.py', '--cfg-path', '/tmp/tmpe1j5be2d']
[2023-08-05T05:50:43.576+0000] {standard_task_runner.py:85} INFO - Job 30: Subtask hit_api
[2023-08-05T05:50:43.608+0000] {task_command.py:410} INFO - Running <TaskInstance: 7_da_temps.hit_api manual__2023-08-05T05:50:42.800896+00:00 [running]> on host 87416e0da69d
[2023-08-05T05:50:43.650+0000] {taskinstance.py:1545} INFO - Exporting env vars: AIRFLOW_CTX_DAG_OWNER='scott' AIRFLOW_CTX_DAG_ID='7_da_temps' AIRFLOW_CTX_TASK_ID='hit_api' AIRFLOW_CTX_EXECUTION_DATE='2023-08-05T05:50:42.800896+00:00' AIRFLOW_CTX_TRY_NUMBER='1' AIRFLOW_CTX_DAG_RUN_ID='manual__2023-08-05T05:50:42.800896+00:00'
[2023-08-05T05:50:43.652+0000] {taskinstance.py:1824} ERROR - Task failed with exception
Traceback (most recent call last):
  File "/home/airflow/.local/lib/python3.11/site-packages/airflow/operators/python.py", line 181, in execute
    return_value = self.execute_callable()
                   ^^^^^^^^^^^^^^^^^^^^^^^
  File "/home/airflow/.local/lib/python3.11/site-packages/airflow/operators/python.py", line 198, in execute_callable
    return self.python_callable(*self.op_args, **self.op_kwargs)
           ^^^^^^^^^^^^^^^^^^^^^^^^^^^^^^^^^^^^^^^^^^^^^^^^^^^^^
  File "/opt/airflow/dags/7_da_weather/7_da_temps.py", line 17, in hit_open_weather
    lat: float = config["HOME_LAT"]
                 ~~~~~~^^^^^^^^^^^^
KeyError: 'HOME_LAT'
[2023-08-05T05:50:43.659+0000] {taskinstance.py:1345} INFO - Marking task as FAILED. dag_id=7_da_temps, task_id=hit_api, execution_date=20230805T055042, start_date=20230805T055043, end_date=20230805T055043
[2023-08-05T05:50:43.863+0000] {standard_task_runner.py:104} ERROR - Failed to execute job 30 for task hit_api ('HOME_LAT'; 453)
[2023-08-05T05:50:43.910+0000] {local_task_job_runner.py:225} INFO - Task exited with return code 1
[2023-08-05T05:50:43.922+0000] {taskinstance.py:2653} INFO - 0 downstream tasks scheduled from follow-on schedule check
