[2023-08-05T05:57:57.979+0000] {taskinstance.py:1103} INFO - Dependencies all met for dep_context=non-requeueable deps ti=<TaskInstance: 7_da_temps.hit_api manual__2023-08-05T05:57:57.424482+00:00 [queued]>
[2023-08-05T05:57:57.984+0000] {taskinstance.py:1103} INFO - Dependencies all met for dep_context=requeueable deps ti=<TaskInstance: 7_da_temps.hit_api manual__2023-08-05T05:57:57.424482+00:00 [queued]>
[2023-08-05T05:57:57.984+0000] {taskinstance.py:1308} INFO - Starting attempt 1 of 1
[2023-08-05T05:57:57.989+0000] {taskinstance.py:1327} INFO - Executing <Task(PythonOperator): hit_api> on 2023-08-05 05:57:57.424482+00:00
[2023-08-05T05:57:57.995+0000] {standard_task_runner.py:57} INFO - Started process 1676 to run task
[2023-08-05T05:57:57.998+0000] {standard_task_runner.py:84} INFO - Running: ['***', 'tasks', 'run', '7_da_temps', 'hit_api', 'manual__2023-08-05T05:57:57.424482+00:00', '--job-id', '34', '--raw', '--subdir', 'DAGS_FOLDER/7_da_weather/7_da_temps.py', '--cfg-path', '/tmp/tmpytem_ogj']
[2023-08-05T05:57:58.001+0000] {standard_task_runner.py:85} INFO - Job 34: Subtask hit_api
[2023-08-05T05:57:58.034+0000] {task_command.py:410} INFO - Running <TaskInstance: 7_da_temps.hit_api manual__2023-08-05T05:57:57.424482+00:00 [running]> on host 87416e0da69d
[2023-08-05T05:57:58.075+0000] {taskinstance.py:1545} INFO - Exporting env vars: AIRFLOW_CTX_DAG_OWNER='scott' AIRFLOW_CTX_DAG_ID='7_da_temps' AIRFLOW_CTX_TASK_ID='hit_api' AIRFLOW_CTX_EXECUTION_DATE='2023-08-05T05:57:57.424482+00:00' AIRFLOW_CTX_TRY_NUMBER='1' AIRFLOW_CTX_DAG_RUN_ID='manual__2023-08-05T05:57:57.424482+00:00'
[2023-08-05T05:57:58.551+0000] {taskinstance.py:1824} ERROR - Task failed with exception
Traceback (most recent call last):
  File "/home/airflow/.local/lib/python3.11/site-packages/airflow/operators/python.py", line 181, in execute
    return_value = self.execute_callable()
                   ^^^^^^^^^^^^^^^^^^^^^^^
  File "/home/airflow/.local/lib/python3.11/site-packages/airflow/operators/python.py", line 198, in execute_callable
    return self.python_callable(*self.op_args, **self.op_kwargs)
           ^^^^^^^^^^^^^^^^^^^^^^^^^^^^^^^^^^^^^^^^^^^^^^^^^^^^^
  File "/opt/airflow/dags/7_da_weather/7_da_temps.py", line 22, in hit_open_weather
    one_call = mgr.one_call(lat=lat, lon=lon)
               ^^^^^^^^^^^^^^^^^^^^^^^^^^^^^^
  File "/home/airflow/.local/lib/python3.11/site-packages/pyowm/weatherapi25/weather_manager.py", line 531, in one_call
    _, json_data = self.http_client.get_json(ONE_CALL_URI, params=params)
                   ^^^^^^^^^^^^^^^^^^^^^^^^^^^^^^^^^^^^^^^^^^^^^^^^^^^^^^
  File "/home/airflow/.local/lib/python3.11/site-packages/pyowm/commons/http_client.py", line 158, in get_json
    HttpClient.check_status_code(resp.status_code, resp.text)
  File "/home/airflow/.local/lib/python3.11/site-packages/pyowm/commons/http_client.py", line 313, in check_status_code
    raise exceptions.UnauthorizedError('Invalid API Key provided')
pyowm.commons.exceptions.UnauthorizedError: Invalid API Key provided
[2023-08-05T05:57:58.564+0000] {taskinstance.py:1345} INFO - Marking task as FAILED. dag_id=7_da_temps, task_id=hit_api, execution_date=20230805T055757, start_date=20230805T055757, end_date=20230805T055758
[2023-08-05T05:57:58.570+0000] {standard_task_runner.py:104} ERROR - Failed to execute job 34 for task hit_api (Invalid API Key provided; 1676)
[2023-08-05T05:57:58.629+0000] {local_task_job_runner.py:225} INFO - Task exited with return code 1
[2023-08-05T05:57:58.642+0000] {taskinstance.py:2653} INFO - 0 downstream tasks scheduled from follow-on schedule check
