[2023-08-06T22:00:17.358+0000] {taskinstance.py:1103} INFO - Dependencies all met for dep_context=non-requeueable deps ti=<TaskInstance: 7_da_temps.hit_api manual__2023-08-06T22:00:16.563203+00:00 [queued]>
[2023-08-06T22:00:17.363+0000] {taskinstance.py:1103} INFO - Dependencies all met for dep_context=requeueable deps ti=<TaskInstance: 7_da_temps.hit_api manual__2023-08-06T22:00:16.563203+00:00 [queued]>
[2023-08-06T22:00:17.364+0000] {taskinstance.py:1308} INFO - Starting attempt 1 of 1
[2023-08-06T22:00:17.369+0000] {taskinstance.py:1327} INFO - Executing <Task(PythonOperator): hit_api> on 2023-08-06 22:00:16.563203+00:00
[2023-08-06T22:00:17.374+0000] {standard_task_runner.py:57} INFO - Started process 4721 to run task
[2023-08-06T22:00:17.377+0000] {standard_task_runner.py:84} INFO - Running: ['***', 'tasks', 'run', '7_da_temps', 'hit_api', 'manual__2023-08-06T22:00:16.563203+00:00', '--job-id', '39', '--raw', '--subdir', 'DAGS_FOLDER/7_da_weather/7_da_temps.py', '--cfg-path', '/tmp/tmpo3a36z3_']
[2023-08-06T22:00:17.380+0000] {standard_task_runner.py:85} INFO - Job 39: Subtask hit_api
[2023-08-06T22:00:17.421+0000] {task_command.py:410} INFO - Running <TaskInstance: 7_da_temps.hit_api manual__2023-08-06T22:00:16.563203+00:00 [running]> on host ed9f4b70d884
[2023-08-06T22:00:17.469+0000] {taskinstance.py:1545} INFO - Exporting env vars: AIRFLOW_CTX_DAG_OWNER='scott' AIRFLOW_CTX_DAG_ID='7_da_temps' AIRFLOW_CTX_TASK_ID='hit_api' AIRFLOW_CTX_EXECUTION_DATE='2023-08-06T22:00:16.563203+00:00' AIRFLOW_CTX_TRY_NUMBER='1' AIRFLOW_CTX_DAG_RUN_ID='manual__2023-08-06T22:00:16.563203+00:00'
[2023-08-06T22:00:19.332+0000] {taskinstance.py:1824} ERROR - Task failed with exception
Traceback (most recent call last):
  File "/home/airflow/.local/lib/python3.11/site-packages/airflow/operators/python.py", line 181, in execute
    return_value = self.execute_callable()
                   ^^^^^^^^^^^^^^^^^^^^^^^
  File "/home/airflow/.local/lib/python3.11/site-packages/airflow/operators/python.py", line 198, in execute_callable
    return self.python_callable(*self.op_args, **self.op_kwargs)
           ^^^^^^^^^^^^^^^^^^^^^^^^^^^^^^^^^^^^^^^^^^^^^^^^^^^^^
  File "/opt/airflow/dags/7_da_weather/7_da_temps.py", line 27, in hit_open_weather
    week_back = mgr.one_call_history(lat=lat, lon=lon, dt=epoch)
                ^^^^^^^^^^^^^^^^^^^^^^^^^^^^^^^^^^^^^^^^^^^^^^^^
  File "/home/airflow/.local/lib/python3.11/site-packages/pyowm/weatherapi25/weather_manager.py", line 566, in one_call_history
    _, json_data = self.http_client.get_json(ONE_CALL_HISTORICAL_URI, params=params)
                   ^^^^^^^^^^^^^^^^^^^^^^^^^^^^^^^^^^^^^^^^^^^^^^^^^^^^^^^^^^^^^^^^^
  File "/home/airflow/.local/lib/python3.11/site-packages/pyowm/commons/http_client.py", line 158, in get_json
    HttpClient.check_status_code(resp.status_code, resp.text)
  File "/home/airflow/.local/lib/python3.11/site-packages/pyowm/commons/http_client.py", line 311, in check_status_code
    raise exceptions.APIRequestError(payload)
pyowm.commons.exceptions.APIRequestError: {"cod":"400","message":"requested time is out of allowed range of 5 days back"}
[2023-08-06T22:00:19.359+0000] {taskinstance.py:1345} INFO - Marking task as FAILED. dag_id=7_da_temps, task_id=hit_api, execution_date=20230806T220016, start_date=20230806T220017, end_date=20230806T220019
[2023-08-06T22:00:19.372+0000] {standard_task_runner.py:104} ERROR - Failed to execute job 39 for task hit_api ({"cod":"400","message":"requested time is out of allowed range of 5 days back"}; 4721)
[2023-08-06T22:00:19.429+0000] {local_task_job_runner.py:225} INFO - Task exited with return code 1
[2023-08-06T22:00:19.442+0000] {taskinstance.py:2653} INFO - 0 downstream tasks scheduled from follow-on schedule check
