[2023-08-10T18:41:21.395+0000] {taskinstance.py:1103} INFO - Dependencies all met for dep_context=non-requeueable deps ti=<TaskInstance: 7_da_temps.hit_open_meteo manual__2023-08-10T18:41:20.116175+00:00 [queued]>
[2023-08-10T18:41:21.399+0000] {taskinstance.py:1103} INFO - Dependencies all met for dep_context=requeueable deps ti=<TaskInstance: 7_da_temps.hit_open_meteo manual__2023-08-10T18:41:20.116175+00:00 [queued]>
[2023-08-10T18:41:21.399+0000] {taskinstance.py:1308} INFO - Starting attempt 1 of 1
[2023-08-10T18:41:21.405+0000] {taskinstance.py:1327} INFO - Executing <Task(PythonOperator): hit_open_meteo> on 2023-08-10 18:41:20.116175+00:00
[2023-08-10T18:41:21.410+0000] {standard_task_runner.py:57} INFO - Started process 181 to run task
[2023-08-10T18:41:21.413+0000] {standard_task_runner.py:84} INFO - Running: ['***', 'tasks', 'run', '7_da_temps', 'hit_open_meteo', 'manual__2023-08-10T18:41:20.116175+00:00', '--job-id', '54', '--raw', '--subdir', 'DAGS_FOLDER/7_da_weather/7_da_temps.py', '--cfg-path', '/tmp/tmp4vnhb31_']
[2023-08-10T18:41:21.416+0000] {standard_task_runner.py:85} INFO - Job 54: Subtask hit_open_meteo
[2023-08-10T18:41:21.480+0000] {task_command.py:410} INFO - Running <TaskInstance: 7_da_temps.hit_open_meteo manual__2023-08-10T18:41:20.116175+00:00 [running]> on host f08f7dfc3531
[2023-08-10T18:41:21.802+0000] {taskinstance.py:1545} INFO - Exporting env vars: AIRFLOW_CTX_DAG_OWNER='scott' AIRFLOW_CTX_DAG_ID='7_da_temps' AIRFLOW_CTX_TASK_ID='hit_open_meteo' AIRFLOW_CTX_EXECUTION_DATE='2023-08-10T18:41:20.116175+00:00' AIRFLOW_CTX_TRY_NUMBER='1' AIRFLOW_CTX_DAG_RUN_ID='manual__2023-08-10T18:41:20.116175+00:00'
[2023-08-10T18:41:21.803+0000] {logging_mixin.py:150} INFO - ['/home/***/.local/bin', '/usr/local/lib/python311.zip', '/usr/local/lib/python3.11', '/usr/local/lib/python3.11/lib-dynload', '/home/***/.local/lib/python3.11/site-packages', '/usr/local/lib/python3.11/site-packages', '/opt/***/dags', '/opt/***/config', '/opt/***/plugins']
[2023-08-10T18:41:21.804+0000] {logging_mixin.py:150} INFO - /opt/utils
[2023-08-10T18:41:21.804+0000] {taskinstance.py:1824} ERROR - Task failed with exception
Traceback (most recent call last):
  File "/home/airflow/.local/lib/python3.11/site-packages/airflow/operators/python.py", line 181, in execute
    return_value = self.execute_callable()
                   ^^^^^^^^^^^^^^^^^^^^^^^
  File "/home/airflow/.local/lib/python3.11/site-packages/airflow/operators/python.py", line 198, in execute_callable
    return self.python_callable(*self.op_args, **self.op_kwargs)
           ^^^^^^^^^^^^^^^^^^^^^^^^^^^^^^^^^^^^^^^^^^^^^^^^^^^^^
  File "/opt/airflow/dags/7_da_weather/7_da_temps.py", line 24, in hit_open_meteo
    print(os.listdir(os.path.abspath("../utils")))
          ^^^^^^^^^^^^^^^^^^^^^^^^^^^^^^^^^^^^^^^
FileNotFoundError: [Errno 2] No such file or directory: '/opt/utils'
[2023-08-10T18:41:21.811+0000] {taskinstance.py:1345} INFO - Marking task as FAILED. dag_id=7_da_temps, task_id=hit_open_meteo, execution_date=20230810T184120, start_date=20230810T184121, end_date=20230810T184121
[2023-08-10T18:41:21.823+0000] {standard_task_runner.py:104} ERROR - Failed to execute job 54 for task hit_open_meteo ([Errno 2] No such file or directory: '/opt/utils'; 181)
[2023-08-10T18:41:21.869+0000] {local_task_job_runner.py:225} INFO - Task exited with return code 1
[2023-08-10T18:41:21.881+0000] {taskinstance.py:2653} INFO - 0 downstream tasks scheduled from follow-on schedule check
